Workbook

Sheet Modell
B1: Wie funktioniert dein Gehalt?
B2: Schritt für Schritt: vom Mindestgehalt bis zur variablen Zulage.
B4: 1. Dein Gehalt besteht aus drei Teilen
B6: A) Sockelgehalt
B7: 40.000 € pro Jahr bei Vollzeit (40 h/Woche). Bei Teilzeit anteilig (26 h = 26/40 × 40.000 = 26.000 €).
B9: B) Bundle-Zulage (je nach Größe deines Teams)
B10: Je mehr Therapeuten in deinem Bundle arbeiten, desto höher dein Gehalt.
B11: Wir rechnen nicht nach Anzahl Köpfen, sondern nach Stunden: die gesamten Wochenstunden aller TH im Bundle geteilt durch 30 — weil 30 h der übliche Vacura-Schnitt für einen TH ist. So ergibt sich dein »TH-Äquivalent«.
B12: Beispiel: 3 Therapeuten à 40 h + 2 à 30 h = 180 h ÷ 30 = 6 TH-Äquivalente.
B13: Pro TH-Äquivalent bekommst du 250 € (für die ersten 4) bzw. 400 € (für 5–9) bzw. 700 € (ab 10) zusätzlich pro Jahr.
B15: C) Variable Zulage
B16: 0 % bis 55 % Zulage auf dein Basis-Gehalt (= Sockel + Bundle-Zulage). Die 6 Stufen siehst du gleich in Abschnitt 2.
... B25: Jede Stufe entspricht einer festen variablen Zulage auf dein Basis-Gehalt:
B27: Stufe | C27: Name | D27: Zulage % | E27: Beispielgehalt Vollzeit, 8 TH
B28: 1 | C28: Basis | D28: 0 % | E28: 42.600 €
B29: 2 | C29: Gut | D29: 11 % | E29: 47.286 €
B30: 3 | C30: Stark | D30: 22 % | E30: 51.972 €
B31: 4 | C31: Sehr stark | D31: 33 % | E31: 56.658 €
B32: 5 | C32: Exzellent | D32: 44 % | E32: 61.344 €
B33: 6 | C33: Herausragend | D33: 55 % | E33: 66.030 €
B36: 3. Wie ergibt sich deine Stufe?
B38: Deine Stufe steht, wenn zwei Sachen gleichzeitig stimmen:
B40: Bedingung 1 — Wirtschaftlich:
B41: Dein Bundle muss einen bestimmten Umsatz pro Therapie-Stunde erwirtschaften.
B42: Zum Beispiel: Für Stufe 3 brauchst du ca. 73 €/Stunde, für Stufe 5 ca. 84 €/Stunde. Details dazu in Abschnitt 4.
B44: Bedingung 2 — Teamzufriedenheit:
B45: Dein Team muss in der anonymen Quartals-Umfrage einen bestimmten Zufriedenheits-Score erreichen (Skala 0–10).
B46: Zum Beispiel: Stufe 3 braucht ≥ 7,0 — Stufe 5 braucht ≥ 8,5.
B48: Beide Schwellen müssen erfüllt sein — nur wirtschaftlich stark ODER nur glückliches Team reicht nicht.
B50: Die Schwellen pro Stufe:
B52: Stufe | C52: €/60min Therapie (min.) | D52: Zufriedenheits-Score (min.)
B53: 1 Basis | C53: 61,17 € | D53: 5,0
B54: 2 Gut | C54: 66,54 € | D54: 6,0
B55: 3 Stark | C55: 72,64 € | D55: 7,0
B56: 4 Sehr stark | C56: 77,28 € | D56: 8,0
B57: 5 Exzellent | C57: 84,11 € | D57: 8,5
B58: 6 Herausragend | C58: 89,48 € | D58: 8,5
B61: 4. Was bedeutet »€/60min Therapie«?
B63: Das ist der Wert, an dem deine Leistung gemessen wird.
B64: Er sagt: Wie viel Umsatz macht dein Bundle durchschnittlich pro Stunde, in der ein TH tatsächlich arbeitet (also nicht im Urlaub oder in Fortbildung ist).
...

Sheet Anleitung Q-Wechsel
A1: 📋 Anleitung Quartalswechsel — Was tun, wenn ein Quartal endet?
A3: Diese Anleitung beschreibt die manuellen Schritte, die nach jedem Quartals-Ende notwendig sind, damit die PM-Bewertung für das Folge-Quartal greift.
A5: Zeitpunkt: spätestens 5. Tag des Folge-Monats (also 5.7., 5.10., 5.1., 5.4.)
A7: Schritt | B7: Was | C7: Wo eintragen | D7: Wer | E7: Warum / Hinweis
A8: 1 | B8: Zufriedenheits-Scores aus Q-Umfrage eintragen | C8: Tab "Daten" — Spalten 11 (Rücken), 12 (Komm), 13 (eNPS) | D8: Du (Geschäftsführung) | E8: Aus quartalsweiser Umfrage (anonym, ≥60% Teilnahme). Formel: Score = 0,2×Rücken + 0,2×Komm + 0,6×eNPS. Ohne diese Werte ist die Stufen-Bewertung unvollständig.
A9: 2 | B9: MediFox-IST-Werte als Sanity-Check eintragen | C9: Tab "Sanity (MediFox)" — pro Bundle eine Zeile | D9: Du (Geschäftsführung) | E9: MediFox-Export pro Standort/Monat, Summen über Q. Wird automatisch mit NocoDB-IST verglichen — Diff > 2 % bedeutet Untersuchung nötig.
A10: 3 | B10: Q-End-Berechnung anstoßen | C10: Routine läuft automatisch am 1. des Folge-Monats | D10: Code (Routine-Agent) | E10: compute_quartal() rechnet für jedes Bundle: IST, Vstd, Abw, Feiertage, eur60, rechn_stufe und tats_stufe (mit ±1-Deckel). Werte werden ins Tab "Audit Q<N>" geschrieben.
A11: 4 | B11: Stufe Vorquartal manuell updaten | C11: Tab "Daten" — Spalte 5 ("Stufe Vorquartal") pro PM | D11: Du (Geschäftsführung) ODER Routine | E11: Die tats_stufe aus dem Audit-Tab wird zur "Stufe Vorquartal" für die nächste Bewertung — wichtig für den ±1-Deckel. Wenn falsch, kann eine PM rechnerisch Stufe 4 sein aber wegen falschem Vorquartals-Wert auf Stufe 1 gedeckelt werden.
A12: 5 | B12: Dashboards regenerieren + deployen | C12: GitHub Action "Regenerate PM Dashboards" manuell triggern | D12: Code (Routine-Agent) | E12: Nach Excel-Update werden die HTML-Dashboards mit Q-Final-Werten neu gebaut und auf GitHub Pages deployed. PMs sehen dann ihre offizielle Q-Bewertung.
A13: 6 | B13: Plausibilitäts-Check + Freigabe | C13: Audit-Tab durchgehen, Diff zu MediFox prüfen | D13: Du (Geschäftsführung) | E13: Wenn Audit-Werte plausibel und MediFox-Diff < 2 %: Q-Bewertung gilt als final, Gehälter werden für das Folge-Quartal angepasst. Sonst: Ursache klären, Werte ggf. nachbessern.
A15: Legende:
A16: Gelb = manuelle Aktion durch Geschäftsführung
A17: Grün = automatisch durch Code/Routine
A20: Detaillierte Berechnungsmethodik | B20: Code-Repo: pm-dashboards/v2/METHODE.md

Sheet Audit Q1 2026
A1: 📋 Audit Q1 2026
A3: Q1 2026 ist HISTORISCH EINGEFROREN. Diese Werte wurden manuell ins Excel eingetragen (Daten-Tab Spalten 7-10) und gelten als Bewertungsgrundlage für das Folgequartal Q2. Bitte NICHT ändern — falls Werte korrigiert werden müssen, beide Stellen synchron halten (Daten-Tab + dieses Audit-Sheet).
A5: Quartals-Fenster: 2026-01-01 bis 2026-03-31
A7: PM | B7: Bundle (Standorte) | C7: Vstd brutto (Bundle) | D7: Vstd ber (Stufen-Basis) | E7: Abw ber (Stufen-Basis) | F7: Feiertage h | G7: IST (€) | H7: Verfueg h | I7: €/h | J7: Zufr-Score | K7: Rechn. Stufe (ohne ±1) | L7: Tats. Stufe (mit ±1) | M7: Probezeit aktiv? | N7: Anzahl TH | O7: Termine erbracht | P7: Stand / Notizen
A8: Laura | B8: Spandau, Mitte | C8: 4924 | D8: 4686.3 | E8: 554.8 | F8: — | G8: 291941 | H8: 4131.5 | I8: 70.662229 | J8: 8.52 | K8: 2 | L8: 2 | M8: Nein | N8: — | O8: — | P8: Excel-Daten-Tab Spalten 7-10, alte Methode (kein konsistenter NA-29T-Abzug, keine Feiertage)
A9: Marleen | B9: Friedrichshain, Charlottenburg, Prenzlauer Berg | C9: 5665.2 | D9: 5343.5 | E9: 293.5 | F9: — | G9: 337924 | H9: 5050 | I9: 66.915644 | J9: 8.24 | K9: 2 | L9: 2 | M9: Nein | N9: — | O9: — | P9: Excel-Daten-Tab Spalten 7-10, alte Methode (kein konsistenter NA-29T-Abzug, keine Feiertage)
A10: Luise | B10: Friedrichshain, Charlottenburg, Prenzlauer Berg | C10: 5665.2 | D10: 5343.5 | E10: 293.5 | F10: — | G10: 337924 | H10: 5050 | I10: 66.915644 | J10: 3.44 | K10: 1 | L10: 1 | M10: Ja | N10: — | O10: — | P10: Excel-Daten-Tab Spalten 7-10, alte Methode (kein konsistenter NA-29T-Abzug, keine Feiertage)
A11: Max | B11: Spandau, Mitte | C11: 4924 | D11: 4686.3 | E11: 554.8 | F11: — | G11: 291941 | H11: 4131.5 | I11: 70.662229 | J11: 8.54 | K11: 1 | L11: 1 | M11: Ja | N11: — | O11: — | P11: Excel-Daten-Tab Spalten 7-10, alte Methode (kein konsistenter NA-29T-Abzug, keine Feiertage)

Sheet Audit Q2 2026
A1: 📋 Audit Q2 2026
A3: Q2 2026 wird AUTOMATISCH durch die Q-End-Routine befüllt (am 1.7.2026). Die Routine ruft compute_quartal(pm, 2026-04-01, 2026-06-30, today=2026-06-30) auf und schreibt die Werte hier rein. Dieses Sheet ist nach dem Q-End-Lauf die offizielle Bewertungsgrundlage für Q3 2026.
A5: Quartals-Fenster: 2026-04-01 bis 2026-06-30
A7: PM | B7: Bundle (Standorte) | C7: Vstd brutto (Bundle) | D7: Vstd ber (Stufen-Basis) | E7: Abw ber (Stufen-Basis) | F7: Feiertage h | G7: IST (€) | H7: Verfueg h | I7: €/h | J7: Zufr-Score | K7: Rechn. Stufe (ohne ±1) | L7: Tats. Stufe (mit ±1) | M7: Probezeit aktiv? | N7: Anzahl TH | O7: Termine erbracht | P7: Stand / Notizen
A8: Laura | B8: Spandau, Mitte | P8: (wird am 1.7.2026 befüllt)
A9: Marleen | B9: Friedrichshain, Charlottenburg, Prenzlauer Berg | P9: (wird am 1.7.2026 befüllt)
A10: Luise | B10: Friedrichshain, Charlottenburg, Prenzlauer Berg | P10: (wird am 1.7.2026 befüllt)
A11: Max | B11: Spandau, Mitte | P11: (wird am 1.7.2026 befüllt)

Sheet Sanity (MediFox)
A1: 📊 MediFox-Sanity-Check pro Quartal
A3: Hier den MediFox-IST-Export pro Bundle eintragen. Diff zu NocoDB-IST wird automatisch berechnet. Akzeptable Toleranz: < 2 % (durch nachgelagerte Abrechnungs-Logik / Verordnungs-Genehmigungen).
A5: Quartal | B5: Bundle | C5: MediFox-IST | D5: NocoDB-IST (Code) | E5: Diff € | F5: Diff %
A6: Q1 2026 | B6: Laura (SP+MI) | C6: 299437 | D6: 293727 | E6: =D6-C6 | F6: =IFERROR((D6-C6)/C6,"")
A7: Q1 2026 | B7: Marleen (FR+CB) | C7: 351752 | D7: 347401 | E7: =D7-C7 | F7: =IFERROR((D7-C7)/C7,"")

Sheet Laura
B1: Laura — Dein Gehaltsmodell
B2: Deine persönliche Übersicht — Gehalt, Stufe und was du für die nächste Stufe brauchst.
B4: 1. Du und dein Bundle
B6: Name: | D6: =Daten!B5
B7: Dein Bundle: | D7: Spandau, Mitte
B8: Wochenstunden: | D8: =Daten!C5
B9: Startdatum: | D9: =IFERROR(TEXT(Daten!A5,"DD.MM.YYYY"),"(seit Anfang)")
B10: Mindestgehalt pro Jahr: | D10: =Daten!F5
B13: 2. Dein aktuelles Gehalt (letztes abgeschlossenes Quartal: Q1 2026)
B15: Dein Monatsgehalt (ab Q2 2026): | D15: =IFERROR(Berechnung!T5,"(fehlt Zufr-Wert)")
B16: Stufe: | D16: =IFERROR(Berechnung!O5 & " - " & Berechnung!P5,"")
B17: Jahresgehalt: | D17: =IFERROR(Berechnung!S5,"")
B19: 3. Warum diese Stufe?
B21: Dein Leistungsindex (€/60min Therapie): | D21: =IFERROR(Daten!J5/(Daten!H5-Daten!I5),"")
B22: Deine Team-Zufriedenheit (0-10): | D22: =IFERROR(Berechnung!C5,"(fehlt Umfrage-Wert)")
B24: Deine erreichte Stufe ergibt sich, wenn BEIDE Werte oben den Schwellen entsprechen (siehe Modell-Tab).
B26: 4. Was bringt dir die nächste Stufe?
B28: Nächste erreichbare Stufe: | D28: =IFERROR((IF(IFERROR(Berechnung!O5,0)<6,IFERROR(Berechnung!O5,0)+1,6)) & " - " & INDEX({"Basis";"Gut";"Stark";"Sehr stark";"Exzellent";"Herausragend"},IF(IFERROR(Berechnung!O5,0)<6,IFERROR(Berechnung!O5,0)+1,6)),"")
B29: Mehr pro Monat (Δ): | D29: =IFERROR(Berechnung!T5*((IFERROR(INDEX(Stufentabelle!E2:E7,IF(IFERROR(Berechnung!O5,0)<6,IFERROR(Berechnung!O5,0)+1,6)),0))-(IFERROR(INDEX(Stufentabelle!E2:E7,Berechnung!O5),0)))/(1+(IFERROR(INDEX(Stufentabelle!E2:E7,Berechnung!O5),0))),"")
B30: Mehr pro Jahr (Δ): | D30: =IFERROR(Berechnung!S5*((IFERROR(INDEX(Stufentabelle!E2:E7,IF(IFERROR(Berechnung!O5,0)<6,IFERROR(Berechnung!O5,0)+1,6)),0))-(IFERROR(INDEX(Stufentabelle!E2:E7,Berechnung!O5),0)))/(1+(IFERROR(INDEX(Stufentabelle!E2:E7,Berechnung!O5),0))),"")
B32: 5. Was fehlt dir für die nächste Stufe?
B34: Zielwert €/60min: | D34: =IFERROR(INDEX(Stufentabelle!F2:F7,IF(IFERROR(Berechnung!O5,0)<6,IFERROR(Berechnung!O5,0)+1,6)),"")
B35: Fehlt dir pro Therapie-Stunde: | D35: =IFERROR(MAX(0,(INDEX(Stufentabelle!F2:F7,IF(IFERROR(Berechnung!O5,0)<6,IFERROR(Berechnung!O5,0)+1,6)))-(Daten!J5/(Daten!H5-Daten!I5))),"")
B36: In Bundle-Umsatz pro Monat: | D36: =IFERROR(MAX(0,((INDEX(Stufentabelle!F2:F7,IF(IFERROR(Berechnung!O5,0)<6,IFERROR(Berechnung!O5,0)+1,6)))*(Daten!H5-Daten!I5)-Daten!J5)/3),"")
B38: 6. Hebel — so schaffst du das
B39: Hinweis: Effekte sind Orientierungswerte (grobe Rechnung), keine exakten Prognosen.
B40: Hebel | C40: Effekt | D40: Praktisch
B41: Mehr Termine pro Woche | C41: +10 Termine/Wo ≈ +3 % Umsatz | D41: Auslastung hoch, Neukunden, Slots besser nutzen
B42: Mehr PKV-Anteil | C42: +1 %-Pkt PKV ≈ +0,7 % Umsatz | D42: Privatpatienten aktiv gewinnen (1,7× Tarif)
B43: Weniger Krankenstand | C43: −1 %-Pkt Krank ≈ +0,5 % Umsatz | D43: Team-Gesundheit, gute Urlaubsplanung
B46: 7. Deine Entwicklung über die Quartale
B48: Quartal | C48: Stufe | D48: €/60min | E48: Monatsgehalt | F48: Jahresgehalt
B49: Q1 2026 | C49: =IFERROR(Berechnung!O5 & " - " & Berechnung!P5,"-") | D49: =IFERROR(Daten!J5/(Daten!H5-Daten!I5),"-") | E49: =IFERROR(Berechnung!T5,"-") | F49: =IFERROR(Berechnung!S5,"-")
B50: Q2 2026 | C50: =IFERROR(Berechnung!AG5 & " - " & Berechnung!AH5,"-") | D50: =IFERROR(Daten!Q5/(Daten!O5-Daten!P5),"-") | E50: =IFERROR(Berechnung!AL5,"-") | F50: =IFERROR(Berechnung!AK5,"-")
B51: Q3 2026 | C51: =IFERROR(Berechnung!AY5 & " - " & Berechnung!AZ5,"-") | D51: =IFERROR(Daten!X5/(Daten!V5-Daten!W5),"-") | E51: =IFERROR(Berechnung!BD5,"-") | F51: =IFERROR(Berechnung!BC5,"-")
B52: Q4 2026 | C52: =IFERROR(Berechnung!BQ5 & " - " & Berechnung!BR5,"-") | D52: =IFERROR(Daten!AE5/(Daten!AC5-Daten!AD5),"-") | E52: =IFERROR(Berechnung!BV5,"-") | F52: =IFERROR(Berechnung!BU5,"-")

Sheet Marleen
B1: Marleen — Dein Gehaltsmodell
B2: Deine persönliche Übersicht — Gehalt, Stufe und was du für die nächste Stufe brauchst.
B4: 1. Du und dein Bundle
B6: Name: | D6: =Daten!B6
B7: Dein Bundle: | D7: Friedrichshain, Charlottenburg, Prenzlauer Berg
B8: Wochenstunden: | D8: =Daten!C6
B9: Startdatum: | D9: =IFERROR(TEXT(Daten!A6,"DD.MM.YYYY"),"(seit Anfang)")
B10: Mindestgehalt pro Jahr: | D10: =Daten!F6
B13: 2. Dein aktuelles Gehalt (letztes abgeschlossenes Quartal: Q1 2026)
B15: Dein Monatsgehalt (ab Q2 2026): | D15: =IFERROR(Berechnung!T6,"(fehlt Zufr-Wert)")
B16: Stufe: | D16: =IFERROR(Berechnung!O6 & " - " & Berechnung!P6,"")
B17: Jahresgehalt: | D17: =IFERROR(Berechnung!S6,"")
B19: 3. Warum diese Stufe?
B21: Dein Leistungsindex (€/60min Therapie): | D21: =IFERROR(Daten!J6/(Daten!H6-Daten!I6),"")
B22: Deine Team-Zufriedenheit (0-10): | D22: =IFERROR(Berechnung!C6,"(fehlt Umfrage-Wert)")
B24: Deine erreichte Stufe ergibt sich, wenn BEIDE Werte oben den Schwellen entsprechen (siehe Modell-Tab).
B26: 4. Was bringt dir die nächste Stufe?
B28: Nächste erreichbare Stufe: | D28: =IFERROR((IF(IFERROR(Berechnung!O6,0)<6,IFERROR(Berechnung!O6,0)+1,6)) & " - " & INDEX({"Basis";"Gut";"Stark";"Sehr stark";"Exzellent";"Herausragend"},IF(IFERROR(Berechnung!O6,0)<6,IFERROR(Berechnung!O6,0)+1,6)),"")
B29: Mehr pro Monat (Δ): | D29: =IFERROR(Berechnung!T6*((IFERROR(INDEX(Stufentabelle!E2:E7,IF(IFERROR(Berechnung!O6,0)<6,IFERROR(Berechnung!O6,0)+1,6)),0))-(IFERROR(INDEX(Stufentabelle!E2:E7,Berechnung!O6),0)))/(1+(IFERROR(INDEX(Stufentabelle!E2:E7,Berechnung!O6),0))),"")
B30: Mehr pro Jahr (Δ): | D30: =IFERROR(Berechnung!S6*((IFERROR(INDEX(Stufentabelle!E2:E7,IF(IFERROR(Berechnung!O6,0)<6,IFERROR(Berechnung!O6,0)+1,6)),0))-(IFERROR(INDEX(Stufentabelle!E2:E7,Berechnung!O6),0)))/(1+(IFERROR(INDEX(Stufentabelle!E2:E7,Berechnung!O6),0))),"")
B32: 5. Was fehlt dir für die nächste Stufe?
B34: Zielwert €/60min: | D34: =IFERROR(INDEX(Stufentabelle!F2:F7,IF(IFERROR(Berechnung!O6,0)<6,IFERROR(Berechnung!O6,0)+1,6)),"")
B35: Fehlt dir pro Therapie-Stunde: | D35: =IFERROR(MAX(0,(INDEX(Stufentabelle!F2:F7,IF(IFERROR(Berechnung!O6,0)<6,IFERROR(Berechnung!O6,0)+1,6)))-(Daten!J6/(Daten!H6-Daten!I6))),"")
B36: In Bundle-Umsatz pro Monat: | D36: =IFERROR(MAX(0,((INDEX(Stufentabelle!F2:F7,IF(IFERROR(Berechnung!O6,0)<6,IFERROR(Berechnung!O6,0)+1,6)))*(Daten!H6-Daten!I6)-Daten!J6)/3),"")
B38: 6. Hebel — so schaffst du das
B39: Hinweis: Effekte sind Orientierungswerte (grobe Rechnung), keine exakten Prognosen.
B40: Hebel | C40: Effekt | D40: Praktisch
B41: Mehr Termine pro Woche | C41: +10 Termine/Wo ≈ +3 % Umsatz | D41: Auslastung hoch, Neukunden, Slots besser nutzen
B42: Mehr PKV-Anteil | C42: +1 %-Pkt PKV ≈ +0,7 % Umsatz | D42: Privatpatienten aktiv gewinnen (1,7× Tarif)
B43: Weniger Krankenstand | C43: −1 %-Pkt Krank ≈ +0,5 % Umsatz | D43: Team-Gesundheit, gute Urlaubsplanung
B46: 7. Deine Entwicklung über die Quartale
B48: Quartal | C48: Stufe | D48: €/60min | E48: Monatsgehalt | F48: Jahresgehalt
B49: Q1 2026 | C49: =IFERROR(Berechnung!O6 & " - " & Berechnung!P6,"-") | D49: =IFERROR(Daten!J6/(Daten!H6-Daten!I6),"-") | E49: =IFERROR(Berechnung!T6,"-") | F49: =IFERROR(Berechnung!S6,"-")
B50: Q2 2026 | C50: =IFERROR(Berechnung!AG6 & " - " & Berechnung!AH6,"-") | D50: =IFERROR(Daten!Q6/(Daten!O6-Daten!P6),"-") | E50: =IFERROR(Berechnung!AL6,"-") | F50: =IFERROR(Berechnung!AK6,"-")
B51: Q3 2026 | C51: =IFERROR(Berechnung!AY6 & " - " & Berechnung!AZ6,"-") | D51: =IFERROR(Daten!X6/(Daten!V6-Daten!W6),"-") | E51: =IFERROR(Berechnung!BD6,"-") | F51: =IFERROR(Berechnung!BC6,"-")
B52: Q4 2026 | C52: =IFERROR(Berechnung!BQ6 & " - " & Berechnung!BR6,"-") | D52: =IFERROR(Daten!AE6/(Daten!AC6-Daten!AD6),"-") | E52: =IFERROR(Berechnung!BV6,"-") | F52: =IFERROR(Berechnung!BU6,"-")

Sheet Luise
B1: Luise — Dein Gehaltsmodell
B2: Deine persönliche Übersicht — Gehalt, Stufe und was du für die nächste Stufe brauchst.
B4: 1. Du und dein Bundle
B6: Name: | D6: =Daten!B7
B7: Dein Bundle: | D7: Friedrichshain, Charlottenburg, Prenzlauer Berg
B8: Wochenstunden: | D8: =Daten!C7
B9: Startdatum: | D9: =IFERROR(TEXT(Daten!A7,"DD.MM.YYYY"),"(seit Anfang)")
B10: Mindestgehalt pro Jahr: | D10: =Daten!F7
B13: 2. Dein aktuelles Gehalt (letztes abgeschlossenes Quartal: Q1 2026)
B15: Dein Monatsgehalt (ab Q2 2026): | D15: =IFERROR(Berechnung!T7,"(fehlt Zufr-Wert)")
B16: Stufe: | D16: =IFERROR(Berechnung!O7 & " - " & Berechnung!P7,"")
B17: Jahresgehalt: | D17: =IFERROR(Berechnung!S7,"")
B19: 3. Warum diese Stufe?
B21: Dein Leistungsindex (€/60min Therapie): | D21: =IFERROR(Daten!J7/(Daten!H7-Daten!I7),"")
B22: Deine Team-Zufriedenheit (0-10): | D22: =IFERROR(Berechnung!C7,"(fehlt Umfrage-Wert)")
B24: Deine erreichte Stufe ergibt sich, wenn BEIDE Werte oben den Schwellen entsprechen (siehe Modell-Tab).
B26: 4. Was bringt dir die nächste Stufe?
B28: Nächste erreichbare Stufe: | D28: =IFERROR((IF(IFERROR(Berechnung!O7,0)<6,IFERROR(Berechnung!O7,0)+1,6)) & " - " & INDEX({"Basis";"Gut";"Stark";"Sehr stark";"Exzellent";"Herausragend"},IF(IFERROR(Berechnung!O7,0)<6,IFERROR(Berechnung!O7,0)+1,6)),"")
B29: Mehr pro Monat (Δ): | D29: =IFERROR(Berechnung!T7*((IFERROR(INDEX(Stufentabelle!E2:E7,IF(IFERROR(Berechnung!O7,0)<6,IFERROR(Berechnung!O7,0)+1,6)),0))-(IFERROR(INDEX(Stufentabelle!E2:E7,Berechnung!O7),0)))/(1+(IFERROR(INDEX(Stufentabelle!E2:E7,Berechnung!O7),0))),"")
B30: Mehr pro Jahr (Δ): | D30: =IFERROR(Berechnung!S7*((IFERROR(INDEX(Stufentabelle!E2:E7,IF(IFERROR(Berechnung!O7,0)<6,IFERROR(Berechnung!O7,0)+1,6)),0))-(IFERROR(INDEX(Stufentabelle!E2:E7,Berechnung!O7),0)))/(1+(IFERROR(INDEX(Stufentabelle!E2:E7,Berechnung!O7),0))),"")
B32: 5. Was fehlt dir für die nächste Stufe?
B34: Zielwert €/60min: | D34: =IFERROR(INDEX(Stufentabelle!F2:F7,IF(IFERROR(Berechnung!O7,0)<6,IFERROR(Berechnung!O7,0)+1,6)),"")
B35: Fehlt dir pro Therapie-Stunde: | D35: =IFERROR(MAX(0,(INDEX(Stufentabelle!F2:F7,IF(IFERROR(Berechnung!O7,0)<6,IFERROR(Berechnung!O7,0)+1,6)))-(Daten!J7/(Daten!H7-Daten!I7))),"")
B36: In Bundle-Umsatz pro Monat: | D36: =IFERROR(MAX(0,((INDEX(Stufentabelle!F2:F7,IF(IFERROR(Berechnung!O7,0)<6,IFERROR(Berechnung!O7,0)+1,6)))*(Daten!H7-Daten!I7)-Daten!J7)/3),"")
B38: 6. Hebel — so schaffst du das
B39: Hinweis: Effekte sind Orientierungswerte (grobe Rechnung), keine exakten Prognosen.
B40: Hebel | C40: Effekt | D40: Praktisch
B41: Mehr Termine pro Woche | C41: +10 Termine/Wo ≈ +3 % Umsatz | D41: Auslastung hoch, Neukunden, Slots besser nutzen
B42: Mehr PKV-Anteil | C42: +1 %-Pkt PKV ≈ +0,7 % Umsatz | D42: Privatpatienten aktiv gewinnen (1,7× Tarif)
B43: Weniger Krankenstand | C43: −1 %-Pkt Krank ≈ +0,5 % Umsatz | D43: Team-Gesundheit, gute Urlaubsplanung
B46: 7. Deine Entwicklung über die Quartale
B48: Quartal | C48: Stufe | D48: €/60min | E48: Monatsgehalt | F48: Jahresgehalt
B49: Q1 2026 | C49: =IFERROR(Berechnung!O7 & " - " & Berechnung!P7,"-") | D49: =IFERROR(Daten!J7/(Daten!H7-Daten!I7),"-") | E49: =IFERROR(Berechnung!T7,"-") | F49: =IFERROR(Berechnung!S7,"-")
B50: Q2 2026 | C50: =IFERROR(Berechnung!AG7 & " - " & Berechnung!AH7,"-") | D50: =IFERROR(Daten!Q7/(Daten!O7-Daten!P7),"-") | E50: =IFERROR(Berechnung!AL7,"-") | F50: =IFERROR(Berechnung!AK7,"-")
B51: Q3 2026 | C51: =IFERROR(Berechnung!AY7 & " - " & Berechnung!AZ7,"-") | D51: =IFERROR(Daten!X7/(Daten!V7-Daten!W7),"-") | E51: =IFERROR(Berechnung!BD7,"-") | F51: =IFERROR(Berechnung!BC7,"-")
B52: Q4 2026 | C52: =IFERROR(Berechnung!BQ7 & " - " & Berechnung!BR7,"-") | D52: =IFERROR(Daten!AE7/(Daten!AC7-Daten!AD7),"-") | E52: =IFERROR(Berechnung!BV7,"-") | F52: =IFERROR(Berechnung!BU7,"-")

Sheet PM-Stammdaten
A1: 👥 PM-Stammdaten (Quelle der Wahrheit für PM-Liste)
A3: Quelle der Wahrheit für die PM-Liste. Code liest beim Start automatisch. ➜ Neuen PM anlegen: einfach neue Zeile anhängen. Spalte 8 (Farbe), 9 (Token) und 10 (Aktiv) dürfen leer bleiben — werden beim nächsten Dashboard-Lauf automatisch befüllt. Token wird automatisch erzeugt und ins Excel zurückgeschrieben.
A5: Name | B5: Wochenstd | C5: PM-Std Bundle | D5: Mindestgehalt | E5: Startdatum | F5: Bundle-Standorte | G5: Bundle-PMs | H5: Farbe (Hex) | I5: URL-Token (32-hex) | J5: Aktiv
A6: Laura | B6: 40 | C6: 65 | D6: 45000 | F6: Spandau, Mitte | G6: Laura, Max | H6: #4CAF50 | I6: 8278b207ba9e80605ae5f1604d696759 | J6: TRUE
A7: Marleen | B7: 40 | C7: 80 | D7: 45000 | F7: Friedrichshain, Charlottenburg, Prenzlauer Berg | G7: Marleen, Luise | H7: #2196F3 | I7: 0093979f8cf4df0f67ec20b6e35e6beb | J7: TRUE
A8: Luise | B8: 40 | C8: 80 | D8: 40000 | E8: 2026-02-01 | F8: Friedrichshain, Charlottenburg, Prenzlauer Berg | G8: Marleen, Luise | H8: #9C27B0 | I8: 52981192518b734a346928ed713bc015 | J8: TRUE
A9: Max | B9: 26 | C9: 65 | D9: 40000 | E9: 2026-02-01 | F9: Spandau, Mitte | G9: Laura, Max | H9: #FF9800 | I9: 5051837ce5b8f243f109306f60136f17 | J9: TRUE
A11: Auto-Befüllung beim Dashboard-Lauf:
A12: • Spalte 8 leer → Default-Farbe #0D595A (Vacura-Teal)
A13: • Spalte 9 leer → Token wird per secrets.token_hex(16) erzeugt + hier eingetragen
A14: • Spalte 10 leer → Aktiv=Ja angenommen. Auf FALSE setzen um PM zu deaktivieren (z.B. Austritt)
A15: • Plus: Daten-Tab Stammdaten-Spalten 1-6 werden parallel gespiegelt, falls dort noch keine Zeile

Sheet Max
B1: Max — Dein Gehaltsmodell
B2: Deine persönliche Übersicht — Gehalt, Stufe und was du für die nächste Stufe brauchst.
B4: 1. Du und dein Bundle
B6: Name: | D6: =Daten!B8
B7: Dein Bundle: | D7: Spandau, Mitte
B8: Wochenstunden: | D8: =Daten!C8
B9: Startdatum: | D9: =IFERROR(TEXT(Daten!A8,"DD.MM.YYYY"),"(seit Anfang)")
B10: Mindestgehalt pro Jahr: | D10: =Daten!F8
B13: 2. Dein aktuelles Gehalt (letztes abgeschlossenes Quartal: Q1 2026)
B15: Dein Monatsgehalt (ab Q2 2026): | D15: =IFERROR(Berechnung!T8,"(fehlt Zufr-Wert)")
B16: Stufe: | D16: =IFERROR(Berechnung!O8 & " - " & Berechnung!P8,"")
B17: Jahresgehalt: | D17: =IFERROR(Berechnung!S8,"")
B19: 3. Warum diese Stufe?
B21: Dein Leistungsindex (€/60min Therapie): | D21: =IFERROR(Daten!J8/(Daten!H8-Daten!I8),"")
B22: Deine Team-Zufriedenheit (0-10): | D22: =IFERROR(Berechnung!C8,"(fehlt Umfrage-Wert)")
B24: Deine erreichte Stufe ergibt sich, wenn BEIDE Werte oben den Schwellen entsprechen (siehe Modell-Tab).
B26: 4. Was bringt dir die nächste Stufe?
B28: Nächste erreichbare Stufe: | D28: =IFERROR((IF(IFERROR(Berechnung!O8,0)<6,IFERROR(Berechnung!O8,0)+1,6)) & " - " & INDEX({"Basis";"Gut";"Stark";"Sehr stark";"Exzellent";"Herausragend"},IF(IFERROR(Berechnung!O8,0)<6,IFERROR(Berechnung!O8,0)+1,6)),"")
B29: Mehr pro Monat (Δ): | D29: =IFERROR(Berechnung!T8*((IFERROR(INDEX(Stufentabelle!E2:E7,IF(IFERROR(Berechnung!O8,0)<6,IFERROR(Berechnung!O8,0)+1,6)),0))-(IFERROR(INDEX(Stufentabelle!E2:E7,Berechnung!O8),0)))/(1+(IFERROR(INDEX(Stufentabelle!E2:E7,Berechnung!O8),0))),"")
B30: Mehr pro Jahr (Δ): | D30: =IFERROR(Berechnung!S8*((IFERROR(INDEX(Stufentabelle!E2:E7,IF(IFERROR(Berechnung!O8,0)<6,IFERROR(Berechnung!O8,0)+1,6)),0))-(IFERROR(INDEX(Stufentabelle!E2:E7,Berechnung!O8),0)))/(1+(IFERROR(INDEX(Stufentabelle!E2:E7,Berechnung!O8),0))),"")
B32: 5. Was fehlt dir für die nächste Stufe?
B34: Zielwert €/60min: | D34: =IFERROR(INDEX(Stufentabelle!F2:F7,IF(IFERROR(Berechnung!O8,0)<6,IFERROR(Berechnung!O8,0)+1,6)),"")
B35: Fehlt dir pro Therapie-Stunde: | D35: =IFERROR(MAX(0,(INDEX(Stufentabelle!F2:F7,IF(IFERROR(Berechnung!O8,0)<6,IFERROR(Berechnung!O8,0)+1,6)))-(Daten!J8/(Daten!H8-Daten!I8))),"")
B36: In Bundle-Umsatz pro Monat: | D36: =IFERROR(MAX(0,((INDEX(Stufentabelle!F2:F7,IF(IFERROR(Berechnung!O8,0)<6,IFERROR(Berechnung!O8,0)+1,6)))*(Daten!H8-Daten!I8)-Daten!J8)/3),"")
B38: 6. Hebel — so schaffst du das
B39: Hinweis: Effekte sind Orientierungswerte (grobe Rechnung), keine exakten Prognosen.
B40: Hebel | C40: Effekt | D40: Praktisch
B41: Mehr Termine pro Woche | C41: +10 Termine/Wo ≈ +3 % Umsatz | D41: Auslastung hoch, Neukunden, Slots besser nutzen
B42: Mehr PKV-Anteil | C42: +1 %-Pkt PKV ≈ +0,7 % Umsatz | D42: Privatpatienten aktiv gewinnen (1,7× Tarif)
B43: Weniger Krankenstand | C43: −1 %-Pkt Krank ≈ +0,5 % Umsatz | D43: Team-Gesundheit, gute Urlaubsplanung
B46: 7. Deine Entwicklung über die Quartale
B48: Quartal | C48: Stufe | D48: €/60min | E48: Monatsgehalt | F48: Jahresgehalt
B49: Q1 2026 | C49: =IFERROR(Berechnung!O8 & " - " & Berechnung!P8,"-") | D49: =IFERROR(Daten!J8/(Daten!H8-Daten!I8),"-") | E49: =IFERROR(Berechnung!T8,"-") | F49: =IFERROR(Berechnung!S8,"-")
B50: Q2 2026 | C50: =IFERROR(Berechnung!AG8 & " - " & Berechnung!AH8,"-") | D50: =IFERROR(Daten!Q8/(Daten!O8-Daten!P8),"-") | E50: =IFERROR(Berechnung!AL8,"-") | F50: =IFERROR(Berechnung!AK8,"-")
B51: Q3 2026 | C51: =IFERROR(Berechnung!AY8 & " - " & Berechnung!AZ8,"-") | D51: =IFERROR(Daten!X8/(Daten!V8-Daten!W8),"-") | E51: =IFERROR(Berechnung!BD8,"-") | F51: =IFERROR(Berechnung!BC8,"-")
B52: Q4 2026 | C52: =IFERROR(Berechnung!BQ8 & " - " & Berechnung!BR8,"-") | D52: =IFERROR(Daten!AE8/(Daten!AC8-Daten!AD8),"-") | E52: =IFERROR(Berechnung!BV8,"-") | F52: =IFERROR(Berechnung!BU8,"-")

Sheet Dashboard
A1: PM-Gehaltsmodell · Dashboard
A2: Übersicht über alle PMs — Stufe und Monatsgehalt aktuelles Quartal (Q1 2026 = Quelle für Q2-Gehalt)
A4: PM | B4: Bundle | C4: Wochenstd. | D4: €/60min Therapie | E4: TH (zuständig) | F4: Zufriedenheits-Score | G4: Q1 Leistungsindex | H4: Q1 Stufe | I4: Monatsgehalt Q2 | J4: Jahresgehalt Q2
A5: =Daten!B5 | B5: Laura + Max (Spandau, Mitte) | C5: =Daten!C5 | D5: =IFERROR(Daten!J5/(Daten!H5-Daten!I5),"") | E5: =IFERROR(Berechnung!E5,"") | F5: =IFERROR(Berechnung!C5,"") | G5: =IFERROR(Berechnung!L5,"") | H5: =IFERROR(Berechnung!O5 & " - " & Berechnung!P5,"") | I5: =IFERROR(Berechnung!T5,"") | J5: =IFERROR(Berechnung!S5,"")
A6: =Daten!B6 | B6: Marleen + Luise (Friedrichshain, Charlottenburg, Prenzlauer Berg) | C6: =Daten!C6 | D6: =IFERROR(Daten!J6/(Daten!H6-Daten!I6),"") | E6: =IFERROR(Berechnung!E6,"") | F6: =IFERROR(Berechnung!C6,"") | G6: =IFERROR(Berechnung!L6,"") | H6: =IFERROR(Berechnung!O6 & " - " & Berechnung!P6,"") | I6: =IFERROR(Berechnung!T6,"") | J6: =IFERROR(Berechnung!S6,"")
A7: =Daten!B7 | B7: Marleen + Luise (Friedrichshain, Charlottenburg, Prenzlauer Berg) | C7: =Daten!C7 | D7: =IFERROR(Daten!J7/(Daten!H7-Daten!I7),"") | E7: =IFERROR(Berechnung!E7,"") | F7: =IFERROR(Berechnung!C7,"") | G7: =IFERROR(Berechnung!L7,"") | H7: =IFERROR(Berechnung!O7 & " - " & Berechnung!P7,"") | I7: =IFERROR(Berechnung!T7,"") | J7: =IFERROR(Berechnung!S7,"")
A8: =Daten!B8 | B8: Laura + Max (Spandau, Mitte) | C8: =Daten!C8 | D8: =IFERROR(Daten!J8/(Daten!H8-Daten!I8),"") | E8: =IFERROR(Berechnung!E8,"") | F8: =IFERROR(Berechnung!C8,"") | G8: =IFERROR(Berechnung!L8,"") | H8: =IFERROR(Berechnung!O8 & " - " & Berechnung!P8,"") | I8: =IFERROR(Berechnung!T8,"") | J8: =IFERROR(Berechnung!S8,"")
A10: Wie lese ich das? Q1-Leistungsindex zeigt wie gut das Bundle im letzten Quartal performt hat. Die Q1-Stufe ergibt sich aus Leistungsindex + Teamzufriedenheits-Score und bestimmt die Zulage ab Q2. Monatsgehalt Q2 ist das neue Gehalt, das ab dem nächsten Quartal greift.

Sheet Daten
A1: PM-Gehaltsmodell · Vacura
A2: GRAU = Stammdaten (du, statisch) · 🤖 GRÜN = Claude aus NocoDB · ✏️ GELB = du aus Team-Umfrage · ROSÉ = Bundle-Scope (du) → Details im Tab »Modell«
A3: Stammdaten | G3: Q1 2026 | N3: Q2 2026 | U3: Q3 2026 | AB3: Q4 2026 | AI3: Q1 2027 | AP3: Q2 2027 | AW3: Q3 2027 | BD3: Bundle-Scope
A4: Startdatum | B4: Name | C4: Wochenstd. | D4: PM-Std. Bundle | E4: Stufe Vorquartal | F4: Mindestgehalt | G4: 🤖 Claude: VStd (Bundle) | H4: 🤖 Claude: VStd (bereinigt) | I4: 🤖 Claude: Abw. (bereinigt) | J4: 🤖 Claude: IST-Umsatz | K4: ✏️ du: Rücken Ø | L4: ✏️ du: Komm. Ø | M4: ✏️ du: eNPS Ø | N4: 🤖 Claude: VStd (Bundle) | O4: 🤖 Claude: VStd (bereinigt) | P4: 🤖 Claude: Abw. (bereinigt) | Q4: 🤖 Claude: IST-Umsatz | R4: ✏️ du: Rücken Ø | S4: ✏️ du: Komm. Ø | T4: ✏️ du: eNPS Ø | U4: 🤖 Claude: VStd (Bundle) | V4: 🤖 Claude: VStd (bereinigt) | W4: 🤖 Claude: Abw. (bereinigt) | X4: 🤖 Claude: IST-Umsatz | Y4: ✏️ du: Rücken Ø | Z4: ✏️ du: Komm. Ø | AA4: ✏️ du: eNPS Ø | AB4: 🤖 Claude: VStd (Bundle) | AC4: 🤖 Claude: VStd (bereinigt) | AD4: 🤖 Claude: Abw. (bereinigt) | AE4: 🤖 Claude: IST-Umsatz | AF4: ✏️ du: Rücken Ø | AG4: ✏️ du: Komm. Ø | AH4: ✏️ du: eNPS Ø | AI4: 🤖 Claude: VStd (Bundle) | AJ4: 🤖 Claude: VStd (bereinigt) | AK4: 🤖 Claude: Abw. (bereinigt) | AL4: 🤖 Claude: IST-Umsatz | AM4: ✏️ du: Rücken Ø | AN4: ✏️ du: Komm. Ø | AO4: ✏️ du: eNPS Ø | AP4: 🤖 Claude: VStd (Bundle) | AQ4: 🤖 Claude: VStd (bereinigt) | AR4: 🤖 Claude: Abw. (bereinigt) | AS4: 🤖 Claude: IST-Umsatz | AT4: ✏️ du: Rücken Ø | AU4: ✏️ du: Komm. Ø | AV4: ✏️ du: eNPS Ø | AW4: 🤖 Claude: VStd (Bundle) | AX4: 🤖 Claude: VStd (bereinigt) | AY4: 🤖 Claude: Abw. (bereinigt) | AZ4: 🤖 Claude: IST-Umsatz | BA4: ✏️ du: Rücken Ø | BB4: ✏️ du: Komm. Ø | BC4: ✏️ du: eNPS Ø | BD4: Standorte (Bundle) | BE4: TH-Namen (optional) | BF4: Wochenstd. Bundle | BG4: Notizen
B5: Laura | C5: 40 | D5: 65 | E5: 1 | F5: 45000 | G5: 4924 | H5: 4686.3 | I5: 554.8 | J5: 291941 | K5: 8.5 | L5: 8 | M5: 8.7 | BD5: spandau, mitte | BG5: Bundle geteilt mit Max
B6: Marleen | C6: 40 | D6: 80 | E6: 1 | F6: 45000 | G6: 5665.2 | H6: 5343.5 | I6: 293.5 | J6: 337924 | K6: 8.5 | L6: 8.7 | M6: 8 | BD6: friedrichshain, charlottenburg, prenzlauer_berg | BG6: Bundle geteilt mit Luise
A7: 46054 | B7: Luise | C7: 40 | D7: 80 | E7: 1 | F7: 40000 | G7: =G6 | H7: =H6 | I7: =I6 | J7: =J6 | K7: 8.5 | L7: 8.7 | N7: =N6 | O7: =O6 | P7: =P6 | Q7: =Q6 | R7: =R6 | S7: =S6 | T7: =T6 | U7: =U6 | ... BC7: =BC6 | BD7: friedrichshain, charlottenburg, prenzlauer_berg | BG7: Daten-Zellen ziehen auf Zeile 6 (Marleen)
A8: 46054 | B8: Max | C8: 26 | D8: 65 | E8: 1 | F8: 40000 | G8: =G5 | H8: =H5 | I8: =I5 | J8: =J5 | K8: 8.5 | L8: 7.8 | M8: 8.8 | N8: =N5 | O8: =O5 | P8: =P5 | Q8: =Q5 | R8: =R5 | S8: =S5 | T8: =T5 | U8: =U5 | ... BC8: =BC5 | BD8: spandau, mitte | BG8: Daten-Zellen ziehen auf Zeile 5 (Laura)
K14: Vertragliche Arbeitszeit | N14: 4000 | O14: 4000
K15: Abwesenheiten | N15: 250 | O15: 750
E16: SP | F16: 35691 | G16: 30905 | H16: 47055 | K16: Krankheitspauschale | N16: 0.9 | O16: 0.9
E17: MI | F17: 50523 | G17: 62728 | H17: 71031 | K17: VND Zeit | N17: 0.825 | O17: 0.825
E18: FR | F18: 77627 | G18: 50952 | H18: 80145 | K18: Mögliche AZ | N18: =((N14-N15)*N16)*N17 | O18: =((O14-O15)*O16)*O17
E19: CB | F19: 36050 | G19: 46048 | H19: 55935
K20: Umsatz pro Stunde | N20: 103 | O20: 103
K22: Zielumsatz | N22: =N18*N20 | O22: =O18*O20
K23: Zielumsatz pro h | N23: =N22/(N14-N15) | O23: =O22/(O14-O15)
K24: Zielumsatz pro 30h | N24: =N23*30*4.33 | O24: =O23*30*4.33

Sheet Berechnung
A1: ⚠ NUR CLAUDE SCHREIBT HIER — bitte NICHT manuell ändern. | PM-Gehaltsmodell · Berechnung (automatisch aus »Daten«)
B2: Automatisch aus Daten-Tab berechnet. Nicht manuell ändern. Relevant: »Tats. Stufe« und »Monatsgehalt«.
B3: PM | C3: Q1 2026 | U3: Q2 2026 | AM3: Q3 2026 | BE3: Q4 2026 | BW3: Q1 2027 | CO3: Q2 2027 | DG3: Q3 2027
B4: Name | C4: Zufr. Score | D4: TH Bundle | E4: TH PM | F4: TH-Anteil € | G4: Basis-Gehalt | H4: Verfüg. Std | I4: Therapiezeit | J4: Puffer | K4: Ziel-Umsatz | L4: Leistungsindex | M4: Rechn. Stufe | N4: Stufe VorQ | O4: Tats. Stufe | P4: Stufenname | Q4: Zulage % | R4: Gehalt (Formel) | S4: Jahresgehalt | T4: Monatsgehalt | U4: Zufr. Score | V4: TH Bundle | W4: TH PM | X4: TH-Anteil € | Y4: Basis-Gehalt | Z4: Verfüg. Std | AA4: Therapiezeit | AB4: Puffer | AC4: Ziel-Umsatz | AD4: Leistungsindex | AE4: Rechn. Stufe | AF4: Stufe VorQ | AG4: Tats. Stufe | AH4: Stufenname | AI4: Zulage % | AJ4: Gehalt (Formel) | AK4: Jahresgehalt | AL4: Monatsgehalt | AM4: Zufr. Score | AN4: TH Bundle | AO4: TH PM | AP4: TH-Anteil € | AQ4: Basis-Gehalt | AR4: Verfüg. Std | AS4: Therapiezeit | AT4: Puffer | AU4: Ziel-Umsatz | AV4: Leistungsindex | AW4: Rechn. Stufe | AX4: Stufe VorQ | AY4: Tats. Stufe | AZ4: Stufenname | BA4: Zulage % | BB4: Gehalt (Formel) | BC4: Jahresgehalt | BD4: Monatsgehalt | BE4: Zufr. Score | BF4: TH Bundle | BG4: TH PM | BH4: TH-Anteil € | BI4: Basis-Gehalt | BJ4: Verfüg. Std | BK4: Therapiezeit | BL4: Puffer | BM4: Ziel-Umsatz | BN4: Leistungsindex | BO4: Rechn. Stufe | BP4: Stufe VorQ | BQ4: Tats. Stufe | BR4: Stufenname | BS4: Zulage % | BT4: Gehalt (Formel) | BU4: Jahresgehalt | BV4: Monatsgehalt | BW4: Zufr. Score | BX4: TH Bundle | BY4: TH PM | BZ4: TH-Anteil € | CA4: Basis-Gehalt | CB4: Verfüg. Std | CC4: Therapiezeit | CD4: Puffer | CE4: Ziel-Umsatz | CF4: Leistungsindex | CG4: Rechn. Stufe | CH4: Stufe VorQ | CI4: Tats. Stufe | CJ4: Stufenname | CK4: Zulage % | CL4: Gehalt (Formel) | CM4: Jahresgehalt | CN4: Monatsgehalt | CO4: Zufr. Score | CP4: TH Bundle | CQ4: TH PM | CR4: TH-Anteil € | CS4: Basis-Gehalt | CT4: Verfüg. Std | CU4: Therapiezeit | CV4: Puffer | CW4: Ziel-Umsatz | CX4: Leistungsindex | CY4: Rechn. Stufe | CZ4: Stufe VorQ | DA4: Tats. Stufe | DB4: Stufenname | DC4: Zulage % | DD4: Gehalt (Formel) | DE4: Jahresgehalt | DF4: Monatsgehalt | DG4: Zufr. Score | DH4: TH Bundle | DI4: TH PM | DJ4: TH-Anteil € | DK4: Basis-Gehalt | DL4: Verfüg. Std | DM4: Therapiezeit | DN4: Puffer | DO4: Ziel-Umsatz | DP4: Leistungsindex | DQ4: Rechn. Stufe | DR4: Stufe VorQ | DS4: Tats. Stufe | DT4: Stufenname | DU4: Zulage % | DV4: Gehalt (Formel) | DW4: Jahresgehalt | DX4: Monatsgehalt
B5: =Daten!B5 | C5: =IF(NOT(Daten!J5<>0),"",ROUND(Daten!K5*0.2+Daten!L5*0.2+Daten!M5*0.6,1)) | D5: =IF(NOT(Daten!J5<>0),"",ROUND(Daten!G5/13/30,0)) | E5: =IF(D5="","",ROUND(D5*Daten!C5/Daten!D5,0)) | F5: =IF(E5="","",IF(AND(Daten!A5<>"",Daten!A5<=DATE(2026,3,31),DATE(2026,3,31)<Daten!A5+180),0,INDEX('TH-Zulagen'!D$2:D$22,E5+1))) | G5: =IF(NOT(Daten!J5<>0),"",Parameter!D7+IF(F5="",0,F5)) | H5: =IF(NOT(Daten!J5<>0),"",Daten!H5-Daten!I5) | I5: =IF(H5="","",H5*Parameter!D4) | J5: =IF(I5="","",I5*(1-Parameter!D5)) | K5: =IF(J5="","",J5*Parameter!D6) | L5: =IF(NOT(Daten!J5<>0),"",ROUND(Daten!J5/K5*110/1.17,1)) | M5: =IF(NOT(Daten!J5<>0),"",IF(AND(L5>=Stufentabelle!B7,C5>=Stufentabelle!D7),6,IF(AND(L5>=Stufentabelle!B6,C5>=Stufentabelle!D6),5,IF(AND(L5>=Stufentabelle!B5,C5>=Stufentabelle!D5),4,IF(AND(L5>=Stufentabelle!B4,C5>=Stufentabelle!D4),3,IF(AND(L5>=Stufentabelle!B3,C5>=Stufentabelle!D3),2,IF(AND(L5>=Stufentabelle!B2,C5>=Stufentabelle!D2),1,0))))))) | N5: =Daten!E5 | O5: =IF(NOT(Daten!J5<>0),"",IF(AND(Daten!A5<>"",Daten!A5<=DATE(2026,3,31),DATE(2026,3,31)<Daten!A5+180),Daten!E5,IF(OR(M5="",M5=0),MAX(N5-1,1),IF(M5>N5+1,N5+1,IF(M5<N5-1,MAX(N5-1,1),M5))))) | P5: =IF(O5="","",CHOOSE(O5,"Basis","Gut","Stark","Sehr stark","Exzellent","Herrausragend")) | Q5: =IF(O5="","",INDEX(Stufentabelle!E2:E7,MATCH(O5,Stufentabelle!A2:A7,0))) | R5: =IF(OR(O5="",G5=""),"",ROUND(G5*(1+Q5)*(Daten!C5/40),0)) | S5: =IF(R5="","",MAX(R5,ROUND(Daten!F5*(Daten!C5/40),0))) | T5: =IF(S5="","",ROUND(S5/12,0)) | U5: =IF(NOT(Daten!Q5<>0),"",ROUND(Daten!R5*0.2+Daten!S5*0.2+Daten!T5*0.6,1)) | V5: =IF(NOT(Daten!Q5<>0),"",ROUND(Daten!N5/13/30,0)) | W5: =IF(V5="","",ROUND(V5*Daten!C5/Daten!D5,0)) | X5: =IF(W5="","",IF(AND(Daten!A5<>"",Daten!A5<=DATE(2026,6,30),DATE(2026,6,30)<Daten!A5+180),0,INDEX('TH-Zulagen'!D$2:D$22,W5+1))) | Y5: =IF(NOT(Daten!Q5<>0),"",Parameter!D7+IF(X5="",0,X5)) | Z5: =IF(NOT(Daten!Q5<>0),"",Daten!O5-Daten!P5) | AA5: =IF(Z5="","",Z5*Parameter!D4) | AB5: =IF(AA5="","",AA5*(1-Parameter!D5)) | AC5: =IF(AB5="","",AB5*Parameter!D6) | AD5: =IF(NOT(Daten!Q5<>0),"",ROUND(Daten!Q5/AC5*110/1.17,1)) | AE5: =IF(NOT(Daten!Q5<>0),"",IF(AND(AD5>=Stufentabelle!B7,U5>=Stufentabelle!D7),6,IF(AND(AD5>=Stufentabelle!B6,U5>=Stufentabelle!D6),5,IF(AND(AD5>=Stufentabelle!B5,U5>=Stufentabelle!D5),4,IF(AND(AD5>=Stufentabelle!B4,U5>=Stufentabelle!D4),3,IF(AND(AD5>=Stufentabelle!B3,U5>=Stufentabelle!D3),2,IF(AND(AD5>=Stufentabelle!B2,U5>=Stufentabelle!D2),1,0))))))) | AF5: =IF(O5="",Daten!E5,O5) | AG5: =IF(NOT(Daten!Q5<>0),"",IF(AND(Daten!A5<>"",Daten!A5<=DATE(2026,6,30),DATE(2026,6,30)<Daten!A5+180),Daten!E5,IF(OR(AE5="",AE5=0),MAX(AF5-1,1),IF(AE5>AF5+1,AF5+1,IF(AE5<AF5-1,MAX(AF5-1,1),AE5))))) | AH5: =IF(AG5="","",CHOOSE(AG5,"Basis","Gut","Stark","Sehr stark","Exzellent","Herrausragend")) | AI5: =IF(AG5="","",INDEX(Stufentabelle!E2:E7,MATCH(AG5,Stufentabelle!A2:A7,0))) | AJ5: =IF(OR(AG5="",Y5=""),"",ROUND(Y5*(1+AI5)*(Daten!C5/40),0)) | AK5: =IF(AJ5="","",MAX(AJ5,ROUND(Daten!F5*(Daten!C5/40),0))) | AL5: =IF(AK5="","",ROUND(AK5/12,0)) | AM5: =IF(NOT(Daten!X5<>0),"",ROUND(Daten!Y5*0.2+Daten!Z5*0.2+Daten!AA5*0.6,1)) | AN5: =IF(NOT(Daten!X5<>0),"",ROUND(Daten!U5/13/30,0)) | AO5: =IF(AN5="","",ROUND(AN5*Daten!C5/Daten!D5,0)) | AP5: =IF(AO5="","",IF(AND(Daten!A5<>"",Daten!A5<=DATE(2026,9,30),DATE(2026,9,30)<Daten!A5+180),0,INDEX('TH-Zulagen'!D$2:D$22,AO5+1))) | AQ5: =IF(NOT(Daten!X5<>0),"",Parameter!D7+IF(AP5="",0,AP5)) | AR5: =IF(NOT(Daten!X5<>0),"",Daten!V5-Daten!W5) | AS5: =IF(AR5="","",AR5*Parameter!D4) | AT5: =IF(AS5="","",AS5*(1-Parameter!D5)) | AU5: =IF(AT5="","",AT5*Parameter!D6) | AV5: =IF(NOT(Daten!X5<>0),"",ROUND(Daten!X5/AU5*110/1.17,1)) | AW5: =IF(NOT(Daten!X5<>0),"",IF(AND(AV5>=Stufentabelle!B7,AM5>=Stufentabelle!D7),6,IF(AND(AV5>=Stufentabelle!B6,AM5>=Stufentabelle!D6),5,IF(AND(AV5>=Stufentabelle!B5,AM5>=Stufentabelle!D5),4,IF(AND(AV5>=Stufentabelle!B4,AM5>=Stufentabelle!D4),3,IF(AND(AV5>=Stufentabelle!B3,AM5>=Stufentabelle!D3),2,IF(AND(AV5>=Stufentabelle!B2,AM5>=Stufentabelle!D2),1,0))))))) | AX5: =IF(AG5="",IF(O5="",Daten!E5,O5),AG5) | AY5: =IF(NOT(Daten!X5<>0),"",IF(AND(Daten!A5<>"",Daten!A5<=DATE(2026,9,30),DATE(2026,9,30)<Daten!A5+180),Daten!E5,IF(OR(AW5="",AW5=0),MAX(AX5-1,1),IF(AW5>AX5+1,AX5+1,IF(AW5<AX5-1,MAX(AX5-1,1),AW5))))) | AZ5: =IF(AY5="","",CHOOSE(AY5,"Basis","Gut","Stark","Sehr stark","Exzellent","Herrausragend")) | BA5: =IF(AY5="","",INDEX(Stufentabelle!E2:E7,MATCH(AY5,Stufentabelle!A2:A7,0))) | BB5: =IF(OR(AY5="",AQ5=""),"",ROUND(AQ5*(1+BA5)*(Daten!C5/40),0)) | BC5: =IF(BB5="","",MAX(BB5,ROUND(Daten!F5*(Daten!C5/40),0))) | BD5: =IF(BC5="","",ROUND(BC5/12,0)) | BE5: =IF(NOT(Daten!AE5<>0),"",ROUND(Daten!AF5*0.2+Daten!AG5*0.2+Daten!AH5*0.6,1)) | BF5: =IF(NOT(Daten!AE5<>0),"",ROUND(Daten!AB5/13/30,0)) | BG5: =IF(BF5="","",ROUND(BF5*Daten!C5/Daten!D5,0)) | BH5: =IF(BG5="","",IF(AND(Daten!A5<>"",Daten!A5<=DATE(2026,12,31),DATE(2026,12,31)<Daten!A5+180),0,INDEX('TH-Zulagen'!D$2:D$22,BG5+1))) | BI5: =IF(NOT(Daten!AE5<>0),"",Parameter!D7+IF(BH5="",0,BH5)) | BJ5: =IF(NOT(Daten!AE5<>0),"",Daten!AC5-Daten!AD5) | BK5: =IF(BJ5="","",BJ5*Parameter!D4) | BL5: =IF(BK5="","",BK5*(1-Parameter!D5)) | BM5: =IF(BL5="","",BL5*Parameter!D6) | BN5: =IF(NOT(Daten!AE5<>0),"",ROUND(Daten!AE5/BM5*110/1.17,1)) | BO5: =IF(NOT(Daten!AE5<>0),"",IF(AND(BN5>=Stufentabelle!B7,BE5>=Stufentabelle!D7),6,IF(AND(BN5>=Stufentabelle!B6,BE5>=Stufentabelle!D6),5,IF(AND(BN5>=Stufentabelle!B5,BE5>=Stufentabelle!D5),4,IF(AND(BN5>=Stufentabelle!B4,BE5>=Stufentabelle!D4),3,IF(AND(BN5>=Stufentabelle!B3,BE5>=Stufentabelle!D3),2,IF(AND(BN5>=Stufentabelle!B2,BE5>=Stufentabelle!D2),1,0))))))) | BP5: =IF(AY5="",IF(AG5="",IF(O5="",Daten!E5,O5),AG5),AY5) | BQ5: =IF(NOT(Daten!AE5<>0),"",IF(AND(Daten!A5<>"",Daten!A5<=DATE(2026,12,31),DATE(2026,12,31)<Daten!A5+180),Daten!E5,IF(OR(BO5="",BO5=0),MAX(BP5-1,1),IF(BO5>BP5+1,BP5+1,IF(BO5<BP5-1,MAX(BP5-1,1),BO5))))) | BR5: =IF(BQ5="","",CHOOSE(BQ5,"Basis","Gut","Stark","Sehr stark","Exzellent","Herrausragend")) | BS5: =IF(BQ5="","",INDEX(Stufentabelle!E2:E7,MATCH(BQ5,Stufentabelle!A2:A7,0))) | BT5: =IF(OR(BQ5="",BI5=""),"",ROUND(BI5*(1+BS5)*(Daten!C5/40),0)) | BU5: =IF(BT5="","",MAX(BT5,ROUND(Daten!F5*(Daten!C5/40),0))) | BV5: =IF(BU5="","",ROUND(BU5/12,0)) | BW5: =IF(NOT(Daten!AL5<>0),"",ROUND(Daten!AM5*0.2+Daten!AN5*0.2+Daten!AO5*0.6,1)) | BX5: =IF(NOT(Daten!AL5<>0),"",ROUND(Daten!AI5/13/30,0)) | BY5: =IF(BX5="","",ROUND(BX5*Daten!C5/Daten!D5,0)) | BZ5: =IF(BY5="","",IF(AND(Daten!A5<>"",Daten!A5<=DATE(2027,3,31),DATE(2027,3,31)<Daten!A5+180),0,INDEX('TH-Zulagen'!D$2:D$22,BY5+1))) | CA5: =IF(NOT(Daten!AL5<>0),"",Parameter!D7+IF(BZ5="",0,BZ5)) | CB5: =IF(NOT(Daten!AL5<>0),"",Daten!AJ5-Daten!AK5) | CC5: =IF(CB5="","",CB5*Parameter!D4) | CD5: =IF(CC5="","",CC5*(1-Parameter!D5)) | CE5: =IF(CD5="","",CD5*Parameter!D6) | CF5: =IF(NOT(Daten!AL5<>0),"",ROUND(Daten!AL5/CE5*110/1.17,1)) | CG5: =IF(NOT(Daten!AL5<>0),"",IF(AND(CF5>=Stufentabelle!B7,BW5>=Stufentabelle!D7),6,IF(AND(CF5>=Stufentabelle!B6,BW5>=Stufentabelle!D6),5,IF(AND(CF5>=Stufentabelle!B5,BW5>=Stufentabelle!D5),4,IF(AND(CF5>=Stufentabelle!B4,BW5>=Stufentabelle!D4),3,IF(AND(CF5>=Stufentabelle!B3,BW5>=Stufentabelle!D3),2,IF(AND(CF5>=Stufentabelle!B2,BW5>=Stufentabelle!D2),1,0))))))) | CH5: =IF(BQ5="",IF(AY5="",IF(AG5="",IF(O5="",Daten!E5,O5),AG5),AY5),BQ5) | CI5: =IF(NOT(Daten!AL5<>0),"",IF(AND(Daten!A5<>"",Daten!A5<=DATE(2027,3,31),DATE(2027,3,31)<Daten!A5+180),Daten!E5,IF(OR(CG5="",CG5=0),MAX(CH5-1,1),IF(CG5>CH5+1,CH5+1,IF(CG5<CH5-1,MAX(CH5-1,1),CG5))))) | CJ5: =IF(CI5="","",CHOOSE(CI5,"Basis","Gut","Stark","Sehr stark","Exzellent","Herrausragend")) | CK5: =IF(CI5="","",INDEX(Stufentabelle!E2:E7,MATCH(CI5,Stufentabelle!A2:A7,0))) | CL5: =IF(OR(CI5="",CA5=""),"",ROUND(CA5*(1+CK5)*(Daten!C5/40),0)) | CM5: =IF(CL5="","",MAX(CL5,ROUND(Daten!F5*(Daten!C5/40),0))) | CN5: =IF(CM5="","",ROUND(CM5/12,0)) | CO5: =IF(NOT(Daten!AS5<>0),"",ROUND(Daten!AT5*0.2+Daten!AU5*0.2+Daten!AV5*0.6,1)) | CP5: =IF(NOT(Daten!AS5<>0),"",ROUND(Daten!AP5/13/30,0)) | CQ5: =IF(CP5="","",ROUND(CP5*Daten!C5/Daten!D5,0)) | CR5: =IF(CQ5="","",IF(AND(Daten!A5<>"",Daten!A5<=DATE(2027,6,30),DATE(2027,6,30)<Daten!A5+180),0,INDEX('TH-Zulagen'!D$2:D$22,CQ5+1))) | CS5: =IF(NOT(Daten!AS5<>0),"",Parameter!D7+IF(CR5="",0,CR5)) | CT5: =IF(NOT(Daten!AS5<>0),"",Daten!AQ5-Daten!AR5) | CU5: =IF(CT5="","",CT5*Parameter!D4) | CV5: =IF(CU5="","",CU5*(1-Parameter!D5)) | CW5: =IF(CV5="","",CV5*Parameter!D6) | CX5: =IF(NOT(Daten!AS5<>0),"",ROUND(Daten!AS5/CW5*110/1.17,1)) | CY5: =IF(NOT(Daten!AS5<>0),"",IF(AND(CX5>=Stufentabelle!B7,CO5>=Stufentabelle!D7),6,IF(AND(CX5>=Stufentabelle!B6,CO5>=Stufentabelle!D6),5,IF(AND(CX5>=Stufentabelle!B5,CO5>=Stufentabelle!D5),4,IF(AND(CX5>=Stufentabelle!B4,CO5>=Stufentabelle!D4),3,IF(AND(CX5>=Stufentabelle!B3,CO5>=Stufentabelle!D3),2,IF(AND(CX5>=Stufentabelle!B2,CO5>=Stufentabelle!D2),1,0))))))) | CZ5: =IF(CI5="",IF(BQ5="",IF(AY5="",IF(AG5="",IF(O5="",Daten!E5,O5),AG5),AY5),BQ5),CI5) | DA5: =IF(NOT(Daten!AS5<>0),"",IF(AND(Daten!A5<>"",Daten!A5<=DATE(2027,6,30),DATE(2027,6,30)<Daten!A5+180),Daten!E5,IF(OR(CY5="",CY5=0),MAX(CZ5-1,1),IF(CY5>CZ5+1,CZ5+1,IF(CY5<CZ5-1,MAX(CZ5-1,1),CY5))))) | DB5: =IF(DA5="","",CHOOSE(DA5,"Basis","Gut","Stark","Sehr stark","Exzellent","Herrausragend")) | DC5: =IF(DA5="","",INDEX(Stufentabelle!E2:E7,MATCH(DA5,Stufentabelle!A2:A7,0))) | DD5: =IF(OR(DA5="",CS5=""),"",ROUND(CS5*(1+DC5)*(Daten!C5/40),0)) | DE5: =IF(DD5="","",MAX(DD5,ROUND(Daten!F5*(Daten!C5/40),0))) | DF5: =IF(DE5="","",ROUND(DE5/12,0)) | DG5: =IF(NOT(Daten!AZ5<>0),"",ROUND(Daten!BA5*0.2+Daten!BB5*0.2+Daten!BC5*0.6,1)) | DH5: =IF(NOT(Daten!AZ5<>0),"",ROUND(Daten!AW5/13/30,0)) | DI5: =IF(DH5="","",ROUND(DH5*Daten!C5/Daten!D5,0)) | DJ5: =IF(DI5="","",IF(AND(Daten!A5<>"",Daten!A5<=DATE(2027,9,30),DATE(2027,9,30)<Daten!A5+180),0,INDEX('TH-Zulagen'!D$2:D$22,DI5+1))) | DK5: =IF(NOT(Daten!AZ5<>0),"",Parameter!D7+IF(DJ5="",0,DJ5)) | DL5: =IF(NOT(Daten!AZ5<>0),"",Daten!AX5-Daten!AY5) | DM5: =IF(DL5="","",DL5*Parameter!D4) | DN5: =IF(DM5="","",DM5*(1-Parameter!D5)) | DO5: =IF(DN5="","",DN5*Parameter!D6) | DP5: =IF(NOT(Daten!AZ5<>0),"",ROUND(Daten!AZ5/DO5*110/1.17,1)) | DQ5: =IF(NOT(Daten!AZ5<>0),"",IF(AND(DP5>=Stufentabelle!B7,DG5>=Stufentabelle!D7),6,IF(AND(DP5>=Stufentabelle!B6,DG5>=Stufentabelle!D6),5,IF(AND(DP5>=Stufentabelle!B5,DG5>=Stufentabelle!D5),4,IF(AND(DP5>=Stufentabelle!B4,DG5>=Stufentabelle!D4),3,IF(AND(DP5>=Stufentabelle!B3,DG5>=Stufentabelle!D3),2,IF(AND(DP5>=Stufentabelle!B2,DG5>=Stufentabelle!D2),1,0))))))) | DR5: =IF(DA5="",IF(CI5="",IF(BQ5="",IF(AY5="",IF(AG5="",IF(O5="",Daten!E5,O5),AG5),AY5),BQ5),CI5),DA5) | DS5: =IF(NOT(Daten!AZ5<>0),"",IF(AND(Daten!A5<>"",Daten!A5<=DATE(2027,9,30),DATE(2027,9,30)<Daten!A5+180),Daten!E5,IF(OR(DQ5="",DQ5=0),MAX(DR5-1,1),IF(DQ5>DR5+1,DR5+1,IF(DQ5<DR5-1,MAX(DR5-1,1),DQ5))))) | DT5: =IF(DS5="","",CHOOSE(DS5,"Basis","Gut","Stark","Sehr stark","Exzellent","Herrausragend")) | DU5: =IF(DS5="","",INDEX(Stufentabelle!E2:E7,MATCH(DS5,Stufentabelle!A2:A7,0))) | DV5: =IF(OR(DS5="",DK5=""),"",ROUND(DK5*(1+DU5)*(Daten!C5/40),0)) | DW5: =IF(DV5="","",MAX(DV5,ROUND(Daten!F5*(Daten!C5/40),0))) | DX5: =IF(DW5="","",ROUND(DW5/12,0))
B6: =Daten!B6 | C6: =IF(NOT(Daten!J6<>0),"",ROUND(Daten!K6*0.2+Daten!L6*0.2+Daten!M6*0.6,1)) | D6: =IF(NOT(Daten!J6<>0),"",ROUND(Daten!G6/13/30,0)) | E6: =IF(D6="","",ROUND(D6*Daten!C6/Daten!D6,0)) | F6: =IF(E6="","",IF(AND(Daten!A6<>"",Daten!A6<=DATE(2026,3,31),DATE(2026,3,31)<Daten!A6+180),0,INDEX('TH-Zulagen'!D$2:D$22,E6+1))) | G6: =IF(NOT(Daten!J6<>0),"",Parameter!D7+IF(F6="",0,F6)) | H6: =IF(NOT(Daten!J6<>0),"",Daten!H6-Daten!I6) | I6: =IF(H6="","",H6*Parameter!D4) | J6: =IF(I6="","",I6*(1-Parameter!D5)) | K6: =IF(J6="","",J6*Parameter!D6) | L6: =IF(NOT(Daten!J6<>0),"",ROUND(Daten!J6/K6*110/1.17,1)) | M6: =IF(NOT(Daten!J6<>0),"",IF(AND(L6>=Stufentabelle!B7,C6>=Stufentabelle!D7),6,IF(AND(L6>=Stufentabelle!B6,C6>=Stufentabelle!D6),5,IF(AND(L6>=Stufentabelle!B5,C6>=Stufentabelle!D5),4,IF(AND(L6>=Stufentabelle!B4,C6>=Stufentabelle!D4),3,IF(AND(L6>=Stufentabelle!B3,C6>=Stufentabelle!D3),2,IF(AND(L6>=Stufentabelle!B2,C6>=Stufentabelle!D2),1,0))))))) | N6: =Daten!E6 | O6: =IF(NOT(Daten!J6<>0),"",IF(AND(Daten!A6<>"",Daten!A6<=DATE(2026,3,31),DATE(2026,3,31)<Daten!A6+180),Daten!E6,IF(OR(M6="",M6=0),MAX(N6-1,1),IF(M6>N6+1,N6+1,IF(M6<N6-1,MAX(N6-1,1),M6))))) | P6: =IF(O6="","",CHOOSE(O6,"Basis","Gut","Stark","Sehr stark","Exzellent","Herrausragend")) | Q6: =IF(O6="","",INDEX(Stufentabelle!E2:E7,MATCH(O6,Stufentabelle!A2:A7,0))) | R6: =IF(OR(O6="",G6=""),"",ROUND(G6*(1+Q6)*(Daten!C6/40),0)) | S6: =IF(R6="","",MAX(R6,ROUND(Daten!F6*(Daten!C6/40),0))) | T6: =IF(S6="","",ROUND(S6/12,0)) | U6: =IF(NOT(Daten!Q6<>0),"",ROUND(Daten!R6*0.2+Daten!S6*0.2+Daten!T6*0.6,1)) | V6: =IF(NOT(Daten!Q6<>0),"",ROUND(Daten!N6/13/30,0)) | W6: =IF(V6="","",ROUND(V6*Daten!C6/Daten!D6,0)) | X6: =IF(W6="","",IF(AND(Daten!A6<>"",Daten!A6<=DATE(2026,6,30),DATE(2026,6,30)<Daten!A6+180),0,INDEX('TH-Zulagen'!D$2:D$22,W6+1))) | Y6: =IF(NOT(Daten!Q6<>0),"",Parameter!D7+IF(X6="",0,X6)) | Z6: =IF(NOT(Daten!Q6<>0),"",Daten!O6-Daten!P6) | AA6: =IF(Z6="","",Z6*Parameter!D4) | AB6: =IF(AA6="","",AA6*(1-Parameter!D5)) | AC6: =IF(AB6="","",AB6*Parameter!D6) | AD6: =IF(NOT(Daten!Q6<>0),"",ROUND(Daten!Q6/AC6*110/1.17,1)) | AE6: =IF(NOT(Daten!Q6<>0),"",IF(AND(AD6>=Stufentabelle!B7,U6>=Stufentabelle!D7),6,IF(AND(AD6>=Stufentabelle!B6,U6>=Stufentabelle!D6),5,IF(AND(AD6>=Stufentabelle!B5,U6>=Stufentabelle!D5),4,IF(AND(AD6>=Stufentabelle!B4,U6>=Stufentabelle!D4),3,IF(AND(AD6>=Stufentabelle!B3,U6>=Stufentabelle!D3),2,IF(AND(AD6>=Stufentabelle!B2,U6>=Stufentabelle!D2),1,0))))))) | AF6: =IF(O6="",Daten!E6,O6) | AG6: =IF(NOT(Daten!Q6<>0),"",IF(AND(Daten!A6<>"",Daten!A6<=DATE(2026,6,30),DATE(2026,6,30)<Daten!A6+180),Daten!E6,IF(OR(AE6="",AE6=0),MAX(AF6-1,1),IF(AE6>AF6+1,AF6+1,IF(AE6<AF6-1,MAX(AF6-1,1),AE6))))) | AH6: =IF(AG6="","",CHOOSE(AG6,"Basis","Gut","Stark","Sehr stark","Exzellent","Herrausragend")) | AI6: =IF(AG6="","",INDEX(Stufentabelle!E2:E7,MATCH(AG6,Stufentabelle!A2:A7,0))) | AJ6: =IF(OR(AG6="",Y6=""),"",ROUND(Y6*(1+AI6)*(Daten!C6/40),0)) | AK6: =IF(AJ6="","",MAX(AJ6,ROUND(Daten!F6*(Daten!C6/40),0))) | AL6: =IF(AK6="","",ROUND(AK6/12,0)) | AM6: =IF(NOT(Daten!X6<>0),"",ROUND(Daten!Y6*0.2+Daten!Z6*0.2+Daten!AA6*0.6,1)) | AN6: =IF(NOT(Daten!X6<>0),"",ROUND(Daten!U6/13/30,0)) | AO6: =IF(AN6="","",ROUND(AN6*Daten!C6/Daten!D6,0)) | AP6: =IF(AO6="","",IF(AND(Daten!A6<>"",Daten!A6<=DATE(2026,9,30),DATE(2026,9,30)<Daten!A6+180),0,INDEX('TH-Zulagen'!D$2:D$22,AO6+1))) | AQ6: =IF(NOT(Daten!X6<>0),"",Parameter!D7+IF(AP6="",0,AP6)) | AR6: =IF(NOT(Daten!X6<>0),"",Daten!V6-Daten!W6) | AS6: =IF(AR6="","",AR6*Parameter!D4) | AT6: =IF(AS6="","",AS6*(1-Parameter!D5)) | AU6: =IF(AT6="","",AT6*Parameter!D6) | AV6: =IF(NOT(Daten!X6<>0),"",ROUND(Daten!X6/AU6*110/1.17,1)) | AW6: =IF(NOT(Daten!X6<>0),"",IF(AND(AV6>=Stufentabelle!B7,AM6>=Stufentabelle!D7),6,IF(AND(AV6>=Stufentabelle!B6,AM6>=Stufentabelle!D6),5,IF(AND(AV6>=Stufentabelle!B5,AM6>=Stufentabelle!D5),4,IF(AND(AV6>=Stufentabelle!B4,AM6>=Stufentabelle!D4),3,IF(AND(AV6>=Stufentabelle!B3,AM6>=Stufentabelle!D3),2,IF(AND(AV6>=Stufentabelle!B2,AM6>=Stufentabelle!D2),1,0))))))) | AX6: =IF(AG6="",IF(O6="",Daten!E6,O6),AG6) | AY6: =IF(NOT(Daten!X6<>0),"",IF(AND(Daten!A6<>"",Daten!A6<=DATE(2026,9,30),DATE(2026,9,30)<Daten!A6+180),Daten!E6,IF(OR(AW6="",AW6=0),MAX(AX6-1,1),IF(AW6>AX6+1,AX6+1,IF(AW6<AX6-1,MAX(AX6-1,1),AW6))))) | AZ6: =IF(AY6="","",CHOOSE(AY6,"Basis","Gut","Stark","Sehr stark","Exzellent","Herrausragend")) | BA6: =IF(AY6="","",INDEX(Stufentabelle!E2:E7,MATCH(AY6,Stufentabelle!A2:A7,0))) | BB6: =IF(OR(AY6="",AQ6=""),"",ROUND(AQ6*(1+BA6)*(Daten!C6/40),0)) | BC6: =IF(BB6="","",MAX(BB6,ROUND(Daten!F6*(Daten!C6/40),0))) | BD6: =IF(BC6="","",ROUND(BC6/12,0)) | BE6: =IF(NOT(Daten!AE6<>0),"",ROUND(Daten!AF6*0.2+Daten!AG6*0.2+Daten!AH6*0.6,1)) | BF6: =IF(NOT(Daten!AE6<>0),"",ROUND(Daten!AB6/13/30,0)) | BG6: =IF(BF6="","",ROUND(BF6*Daten!C6/Daten!D6,0)) | BH6: =IF(BG6="","",IF(AND(Daten!A6<>"",Daten!A6<=DATE(2026,12,31),DATE(2026,12,31)<Daten!A6+180),0,INDEX('TH-Zulagen'!D$2:D$22,BG6+1))) | BI6: =IF(NOT(Daten!AE6<>0),"",Parameter!D7+IF(BH6="",0,BH6)) | BJ6: =IF(NOT(Daten!AE6<>0),"",Daten!AC6-Daten!AD6) | BK6: =IF(BJ6="","",BJ6*Parameter!D4) | BL6: =IF(BK6="","",BK6*(1-Parameter!D5)) | BM6: =IF(BL6="","",BL6*Parameter!D6) | BN6: =IF(NOT(Daten!AE6<>0),"",ROUND(Daten!AE6/BM6*110/1.17,1)) | BO6: =IF(NOT(Daten!AE6<>0),"",IF(AND(BN6>=Stufentabelle!B7,BE6>=Stufentabelle!D7),6,IF(AND(BN6>=Stufentabelle!B6,BE6>=Stufentabelle!D6),5,IF(AND(BN6>=Stufentabelle!B5,BE6>=Stufentabelle!D5),4,IF(AND(BN6>=Stufentabelle!B4,BE6>=Stufentabelle!D4),3,IF(AND(BN6>=Stufentabelle!B3,BE6>=Stufentabelle!D3),2,IF(AND(BN6>=Stufentabelle!B2,BE6>=Stufentabelle!D2),1,0))))))) | BP6: =IF(AY6="",IF(AG6="",IF(O6="",Daten!E6,O6),AG6),AY6) | BQ6: =IF(NOT(Daten!AE6<>0),"",IF(AND(Daten!A6<>"",Daten!A6<=DATE(2026,12,31),DATE(2026,12,31)<Daten!A6+180),Daten!E6,IF(OR(BO6="",BO6=0),MAX(BP6-1,1),IF(BO6>BP6+1,BP6+1,IF(BO6<BP6-1,MAX(BP6-1,1),BO6))))) | BR6: =IF(BQ6="","",CHOOSE(BQ6,"Basis","Gut","Stark","Sehr stark","Exzellent","Herrausragend")) | BS6: =IF(BQ6="","",INDEX(Stufentabelle!E2:E7,MATCH(BQ6,Stufentabelle!A2:A7,0))) | BT6: =IF(OR(BQ6="",BI6=""),"",ROUND(BI6*(1+BS6)*(Daten!C6/40),0)) | BU6: =IF(BT6="","",MAX(BT6,ROUND(Daten!F6*(Daten!C6/40),0))) | BV6: =IF(BU6="","",ROUND(BU6/12,0)) | BW6: =IF(NOT(Daten!AL6<>0),"",ROUND(Daten!AM6*0.2+Daten!AN6*0.2+Daten!AO6*0.6,1)) | BX6: =IF(NOT(Daten!AL6<>0),"",ROUND(Daten!AI6/13/30,0)) | BY6: =IF(BX6="","",ROUND(BX6*Daten!C6/Daten!D6,0)) | BZ6: =IF(BY6="","",IF(AND(Daten!A6<>"",Daten!A6<=DATE(2027,3,31),DATE(2027,3,31)<Daten!A6+180),0,INDEX('TH-Zulagen'!D$2:D$22,BY6+1))) | CA6: =IF(NOT(Daten!AL6<>0),"",Parameter!D7+IF(BZ6="",0,BZ6)) | CB6: =IF(NOT(Daten!AL6<>0),"",Daten!AJ6-Daten!AK6) | CC6: =IF(CB6="","",CB6*Parameter!D4) | CD6: =IF(CC6="","",CC6*(1-Parameter!D5)) | CE6: =IF(CD6="","",CD6*Parameter!D6) | CF6: =IF(NOT(Daten!AL6<>0),"",ROUND(Daten!AL6/CE6*110/1.17,1)) | CG6: =IF(NOT(Daten!AL6<>0),"",IF(AND(CF6>=Stufentabelle!B7,BW6>=Stufentabelle!D7),6,IF(AND(CF6>=Stufentabelle!B6,BW6>=Stufentabelle!D6),5,IF(AND(CF6>=Stufentabelle!B5,BW6>=Stufentabelle!D5),4,IF(AND(CF6>=Stufentabelle!B4,BW6>=Stufentabelle!D4),3,IF(AND(CF6>=Stufentabelle!B3,BW6>=Stufentabelle!D3),2,IF(AND(CF6>=Stufentabelle!B2,BW6>=Stufentabelle!D2),1,0))))))) | CH6: =IF(BQ6="",IF(AY6="",IF(AG6="",IF(O6="",Daten!E6,O6),AG6),AY6),BQ6) | CI6: =IF(NOT(Daten!AL6<>0),"",IF(AND(Daten!A6<>"",Daten!A6<=DATE(2027,3,31),DATE(2027,3,31)<Daten!A6+180),Daten!E6,IF(OR(CG6="",CG6=0),MAX(CH6-1,1),IF(CG6>CH6+1,CH6+1,IF(CG6<CH6-1,MAX(CH6-1,1),CG6))))) | CJ6: =IF(CI6="","",CHOOSE(CI6,"Basis","Gut","Stark","Sehr stark","Exzellent","Herrausragend")) | CK6: =IF(CI6="","",INDEX(Stufentabelle!E2:E7,MATCH(CI6,Stufentabelle!A2:A7,0))) | CL6: =IF(OR(CI6="",CA6=""),"",ROUND(CA6*(1+CK6)*(Daten!C6/40),0)) | CM6: =IF(CL6="","",MAX(CL6,ROUND(Daten!F6*(Daten!C6/40),0))) | CN6: =IF(CM6="","",ROUND(CM6/12,0)) | CO6: =IF(NOT(Daten!AS6<>0),"",ROUND(Daten!AT6*0.2+Daten!AU6*0.2+Daten!AV6*0.6,1)) | CP6: =IF(NOT(Daten!AS6<>0),"",ROUND(Daten!AP6/13/30,0)) | CQ6: =IF(CP6="","",ROUND(CP6*Daten!C6/Daten!D6,0)) | CR6: =IF(CQ6="","",IF(AND(Daten!A6<>"",Daten!A6<=DATE(2027,6,30),DATE(2027,6,30)<Daten!A6+180),0,INDEX('TH-Zulagen'!D$2:D$22,CQ6+1))) | CS6: =IF(NOT(Daten!AS6<>0),"",Parameter!D7+IF(CR6="",0,CR6)) | CT6: =IF(NOT(Daten!AS6<>0),"",Daten!AQ6-Daten!AR6) | CU6: =IF(CT6="","",CT6*Parameter!D4) | CV6: =IF(CU6="","",CU6*(1-Parameter!D5)) | CW6: =IF(CV6="","",CV6*Parameter!D6) | CX6: =IF(NOT(Daten!AS6<>0),"",ROUND(Daten!AS6/CW6*110/1.17,1)) | CY6: =IF(NOT(Daten!AS6<>0),"",IF(AND(CX6>=Stufentabelle!B7,CO6>=Stufentabelle!D7),6,IF(AND(CX6>=Stufentabelle!B6,CO6>=Stufentabelle!D6),5,IF(AND(CX6>=Stufentabelle!B5,CO6>=Stufentabelle!D5),4,IF(AND(CX6>=Stufentabelle!B4,CO6>=Stufentabelle!D4),3,IF(AND(CX6>=Stufentabelle!B3,CO6>=Stufentabelle!D3),2,IF(AND(CX6>=Stufentabelle!B2,CO6>=Stufentabelle!D2),1,0))))))) | CZ6: =IF(CI6="",IF(BQ6="",IF(AY6="",IF(AG6="",IF(O6="",Daten!E6,O6),AG6),AY6),BQ6),CI6) | DA6: =IF(NOT(Daten!AS6<>0),"",IF(AND(Daten!A6<>"",Daten!A6<=DATE(2027,6,30),DATE(2027,6,30)<Daten!A6+180),Daten!E6,IF(OR(CY6="",CY6=0),MAX(CZ6-1,1),IF(CY6>CZ6+1,CZ6+1,IF(CY6<CZ6-1,MAX(CZ6-1,1),CY6))))) | DB6: =IF(DA6="","",CHOOSE(DA6,"Basis","Gut","Stark","Sehr stark","Exzellent","Herrausragend")) | DC6: =IF(DA6="","",INDEX(Stufentabelle!E2:E7,MATCH(DA6,Stufentabelle!A2:A7,0))) | DD6: =IF(OR(DA6="",CS6=""),"",ROUND(CS6*(1+DC6)*(Daten!C6/40),0)) | DE6: =IF(DD6="","",MAX(DD6,ROUND(Daten!F6*(Daten!C6/40),0))) | DF6: =IF(DE6="","",ROUND(DE6/12,0)) | DG6: =IF(NOT(Daten!AZ6<>0),"",ROUND(Daten!BA6*0.2+Daten!BB6*0.2+Daten!BC6*0.6,1)) | DH6: =IF(NOT(Daten!AZ6<>0),"",ROUND(Daten!AW6/13/30,0)) | DI6: =IF(DH6="","",ROUND(DH6*Daten!C6/Daten!D6,0)) | DJ6: =IF(DI6="","",IF(AND(Daten!A6<>"",Daten!A6<=DATE(2027,9,30),DATE(2027,9,30)<Daten!A6+180),0,INDEX('TH-Zulagen'!D$2:D$22,DI6+1))) | DK6: =IF(NOT(Daten!AZ6<>0),"",Parameter!D7+IF(DJ6="",0,DJ6)) | DL6: =IF(NOT(Daten!AZ6<>0),"",Daten!AX6-Daten!AY6) | DM6: =IF(DL6="","",DL6*Parameter!D4) | DN6: =IF(DM6="","",DM6*(1-Parameter!D5)) | DO6: =IF(DN6="","",DN6*Parameter!D6) | DP6: =IF(NOT(Daten!AZ6<>0),"",ROUND(Daten!AZ6/DO6*110/1.17,1)) | DQ6: =IF(NOT(Daten!AZ6<>0),"",IF(AND(DP6>=Stufentabelle!B7,DG6>=Stufentabelle!D7),6,IF(AND(DP6>=Stufentabelle!B6,DG6>=Stufentabelle!D6),5,IF(AND(DP6>=Stufentabelle!B5,DG6>=Stufentabelle!D5),4,IF(AND(DP6>=Stufentabelle!B4,DG6>=Stufentabelle!D4),3,IF(AND(DP6>=Stufentabelle!B3,DG6>=Stufentabelle!D3),2,IF(AND(DP6>=Stufentabelle!B2,DG6>=Stufentabelle!D2),1,0))))))) | DR6: =IF(DA6="",IF(CI6="",IF(BQ6="",IF(AY6="",IF(AG6="",IF(O6="",Daten!E6,O6),AG6),AY6),BQ6),CI6),DA6) | DS6: =IF(NOT(Daten!AZ6<>0),"",IF(AND(Daten!A6<>"",Daten!A6<=DATE(2027,9,30),DATE(2027,9,30)<Daten!A6+180),Daten!E6,IF(OR(DQ6="",DQ6=0),MAX(DR6-1,1),IF(DQ6>DR6+1,DR6+1,IF(DQ6<DR6-1,MAX(DR6-1,1),DQ6))))) | DT6: =IF(DS6="","",CHOOSE(DS6,"Basis","Gut","Stark","Sehr stark","Exzellent","Herrausragend")) | DU6: =IF(DS6="","",INDEX(Stufentabelle!E2:E7,MATCH(DS6,Stufentabelle!A2:A7,0))) | DV6: =IF(OR(DS6="",DK6=""),"",ROUND(DK6*(1+DU6)*(Daten!C6/40),0)) | DW6: =IF(DV6="","",MAX(DV6,ROUND(Daten!F6*(Daten!C6/40),0))) | DX6: =IF(DW6="","",ROUND(DW6/12,0))
